<?xml version="1.0"?>
<robot name="simple_humanoid_arm">

  <link name="world" />

  <joint name="base_joint" type="fixed">
    <parent link="world"/>
    <child link="base_link"/>
    <origin xyz="0 0 0" rpy="0 0 0"/>
  </joint>

  <link name="base_link">
    <visual>
      <geometry><box size="0.1 0.1 0.05"/></geometry>
      <material name="grey"><color rgba="0.5 0.5 0.5 1"/></material>
    </visual>
  </link>

  <joint name="shoulder_joint" type="revolute">
    <parent link="base_link"/>
    <child link="upper_arm_link"/>
    <origin xyz="0 0 0.075" rpy="0 1 0"/>
    <axis xyz="0 1 0"/>
    <limit lower="-1.57" upper="1.57" effort="100" velocity="0.5"/>
  </joint>

  <link name="upper_arm_link">
    <visual>
      <geometry><cylinder radius="0.03" length="0.2"/></geometry>
      <origin xyz="0 0 0.1" rpy="0 0 0"/>
      <material name="blue"><color rgba="0 0 0.8 1"/></material>
    </visual>
  </link>

  <joint name="elbow_joint" type="revolute">
    <parent link="upper_arm_link"/>
    <child link="lower_arm_link"/>
    <origin xyz="0 0 0.2" rpy="0 1 0"/>
    <axis xyz="0 1 0"/>
    <limit lower="-1.57" upper="1.57" effort="100" velocity="0.5"/>
  </joint>

  <link name="lower_arm_link">
    <visual>
      <geometry><cylinder radius="0.025" length="0.15"/></geometry>
      <origin xyz="0 0 0.075" rpy="0 0 0"/>
      <material name="green"><color rgba="0 0.8 0 1"/></material>
    </visual>
  </link>

  <!-- Placeholder for an end-effector or gripper -->
  <joint name="wrist_joint" type="fixed">
    <parent link="lower_arm_link"/>
    <child link="end_effector_link"/>
    <origin xyz="0 0 0.15" rpy="0 0 0"/>
  </joint>

  <link name="end_effector_link">
    <visual>
      <geometry><box size="0.05 0.05 0.05"/></geometry>
      <material name="red"><color rgba="0.8 0 0 1"/></material>
    </visual>
  </link>

</robot>
